Workbook

Sheet Summary
A1: Kitchen v2 - Cut list & materials summary
A2: Material: 3/4" PVC board (18 mm) for every cabinet panel; 6 mm PVC for toe-kick drawer bottoms.
A4: Item | B4: Value | C4: Unit | D4: Basis
A5: PVC 18 mm pieces | B5: =SUMIFS('Cut List'!$D$5:$D$154,'Cut List'!$H$5:$H$154,"PVC board 18 mm") -> 144 | C5: pcs | D5: Cut List
A6: PVC 18 mm part area | B6: =SUMIFS('Cut List'!$I$5:$I$154,'Cut List'!$H$5:$H$154,"PVC board 18 mm") -> 32.564857 | C6: m² | D6: Cut List
A7: PVC 18 mm sheets (4x8) | B7: 12 | C7: sheets | D7: Nested by make_kitchen_cutlist.py (4 mm kerf, 5 mm trim) - see Sheet Layout / PDF
A8: PVC 18 mm sheet yield | B8: =B6/(B7*2.44*1.22) -> 0.91162931 | C8: % | D8: part area / sheet area
A9: PVC 6 mm pieces | B9: =SUMIFS('Cut List'!$D$5:$D$154,'Cut List'!$H$5:$H$154,"PVC board 6 mm") -> 5 | C9: pcs | D9: Cut List
A10: PVC 6 mm sheets (4x8) | B10: 1 | C10: sheets | D10: Nested (toe-kick drawer bottoms)
A11: Countertop pieces | B11: =SUMIFS('Cut List'!$D$5:$D$154,'Cut List'!$H$5:$H$154,"Countertop 38 mm") -> 3 | C11: pcs | D11: Fabricator templates on site
A12: Hinges | B12: ='Fronts & Hinges'!H32 -> 25 | C12: pcs | D12: Fronts & Hinges sheet
A15: Tip: buy 1 spare 18 mm sheet for cutting mistakes and future repairs.

Sheet Materials
A1: List of materials
A2: Quantities in black are formulas; blue are counts taken from the model or rules of thumb (see Basis). Add a Unit Price column for your supplier quotes.
A4: Category | B4: Item | C4: Specification | D4: Qty | E4: Unit | F4: Basis / note
A5: Board | B5: PVC board 3/4" (18 mm), 4x8 ft | C5: 1220 x 2440 x 18 | D5: =Summary!B7 -> 12 | E5: sheets | F5: Nested sheets (Summary). +1 spare recommended
A6: Board | B6: PVC board 6 mm, 4x8 ft | C6: 1220 x 2440 x 6 | D6: =Summary!B10 -> 1 | E6: sheets | F6: Toe-kick drawer bottoms; offcuts usable for small parts
A7: Countertop | B7: Countertop - Island | C7: 1726 x 953 x 38, solid surface / granite, cooktop cut-out 700x400 | D7: 1 | E7: pc | F7: Solid surface / granite / quartz; fabricator measures on site
A8: Countertop | B8: Countertop - Sink_Counter | C8: 1300 x 635 x 38, solid surface / granite, sink cut-out 770x420 | D8: 1 | E8: pc | F8: Solid surface / granite / quartz; fabricator measures on site
A9: Countertop | B9: Countertop - Washer_Bay | C9: 671 x 635 x 38, solid surface / granite, corner notch 144x144 for pipe | D9: 1 | E9: pc | F9: Solid surface / granite / quartz; fabricator measures on site
A10: Fittings | B10: Concealed hinge 35 mm, soft-close, clip-on | C10: full overlay | D10: =Summary!B12 -> 25 | E10: pcs | F10: Fronts & Hinges sheet
A11: Fittings | B11: Handles or push-to-open latches | C11: per door / drawer front | D11: ='Fronts & Hinges'!I32 -> 22 | E11: pcs | F11: Toe-kick drawers excluded (push-to-open runners)
A12: Fasteners | B12: Screws for PVC board (confirmat 7x50 or 4x40 coarse-thread) | C12: carcass joints | D12: =ROUND(4*Summary!B5,-1) -> 580 | E12: pcs | F12: ~4 per panel (rule of thumb); pre-drill PVC
A13: Fasteners | B13: Short screws 4x16 (hinges, runners, rails) | C13: fittings | D13: =8*Summary!B12+12*SUMIFS(D:D,B:B,"*runner pair*") -> 404 | E13: pcs | F13: 4 per hinge plate+cup, 6 per runner side
A14: Wall mount | B14: Wall-cabinet hanging bracket (adjustable) + rail | C14: pair per cabinet | D14: 10 | E14: pcs | F14: 5 wall cabinets in the model x 2
A15: Wall mount | B15: Masonry anchors / screws 8 mm | C15: for brackets + rails | D15: 20 | E15: pcs | F15: 2 per bracket
A16: Finishing | B16: PVC edge band 22 mm (optional) | C16: door / drawer front edges | D16: =ROUNDUP('Fronts & Hinges'!J32*1.1,0) -> 55 | E16: m | F16: PVC board edges can stay bare; +10% waste
A17: Finishing | B17: Neutral-cure silicone, white/clear | C17: sink, countertop joints, backsplash | D17: 3 | E17: tubes | F17: rule of thumb
A18: Fittings | B18: Shelf pins (5 mm, 32 mm system) | D18: 24 | E18: pcs | F18: Over_Ref_Cabinet, Upper_400, Upper_Hood_620, Upper_Over_Washer
A19: Racks & runners | B19: Toe-kick drawer runner pair 400 mm, low profile, push-to-open | D19: 5 | E19: pcs | F19: Base_Racks_400, Base_Sink_900, Island_1_Racks_450, Island_2_Induction_750, Island_3_Racks_450
A20: Racks & runners | B20: Under-sink pull-out tray (door-mounted cabinet) | C20: 839 W x 450 D x 120 H | D20: 1 | E20: pcs | F20: Base_Sink_900
A21: Racks & runners | B21: Full-extension soft-close runner pair, 450 mm | D21: 1 | E21: pcs | F21: Base_Sink_900
A22: Racks & runners | B22: Pot / pan basket (400 cabinet size, 364 clear, 500 runners) | C22: 339 W x 500 D x 200 H | D22: 1 | E22: pcs | F22: Base_Racks_400
A23: Racks & runners | B23: Full-extension soft-close runner pair, 500 mm | D23: 11 | E23: pcs | F23: Base_Racks_400, Island_1_Racks_450, Island_2_Induction_750, Island_3_Racks_450
A24: Racks & runners | B24: Bowl + plate basket (400 cabinet size, 364 clear, 500 runners) | C24: 339 W x 500 D x 150 H | D24: 1 | E24: pcs | F24: Base_Racks_400
A25: Racks & runners | B25: Cutlery / utensil tray (400 cabinet size, 364 clear, 500 runners) | C25: 339 W x 500 D x 70 H | D25: 1 | E25: pcs | F25: Base_Racks_400
A26: Appliance fit | B26: Flat duct 204x60 + 150 round-to-flat adapter, up the cabinet back to the ceiling (cut-out in the cabinet top) | D26: 1 | E26: pcs | F26: Upper_Hood_620
A27: Appliance fit | B27: Built-in telescopic range hood 60 cm (body <= 560 W for a 584 clear cabinet), ducted, 150 outlet | C27: 560 W x 280 D x 180 H | D27: 1 | E27: pcs | F27: Upper_Hood_620
A28: Finishing | B28: Paint / wrap the exposed pipe (counter -> wall cabinet) to match the backsplash | C28: 458 H section | D28: 1 | E28: lot | F28: Washer_Bay
A29: Racks & runners | B29: Dish drainer drip tray | C29: 854 W x 274 D x 25 H | D29: 1 | E29: pcs | F29: Upper_Sink_900
A30: Racks & runners | B30: Dish drainer, plate tier (900 cabinet) | C30: 854 W x 274 D x 120 H | D30: 1 | E30: pcs | F30: Upper_Sink_900
A31: Racks & runners | B31: Dish drainer, cup / bowl tier (900 cabinet) | C31: 854 W x 274 D x 80 H | D31: 1 | E31: pcs | F31: Upper_Sink_900
A32: Racks & runners | B32: Pot / pan basket (450 cabinet size, 414 clear, 500 runners) | C32: 389 W x 500 D x 200 H | D32: 2 | E32: pcs | F32: Island_1_Racks_450, Island_3_Racks_450
A33: Racks & runners | B33: Bowl + plate basket (450 cabinet size, 414 clear, 500 runners) | C33: 389 W x 500 D x 150 H | D33: 2 | E33: pcs | F33: Island_1_Racks_450, Island_3_Racks_450
A34: Racks & runners | B34: Cutlery / utensil tray (450 cabinet size, 414 clear, 500 runners) | C34: 389 W x 500 D x 70 H | D34: 2 | E34: pcs | F34: Island_1_Racks_450, Island_3_Racks_450
A35: Racks & runners | B35: Deep pot basket (750 cabinet size, 714 clear, 500 runners) | C35: 689 W x 500 D x 250 H | D35: 1 | E35: pcs | F35: Island_2_Induction_750
A36: Racks & runners | B36: Pot / pan basket (750 cabinet size, 714 clear, 500 runners) | C36: 689 W x 500 D x 200 H | D36: 1 | E36: pcs | F36: Island_2_Induction_750
A37: Appliance fit | B37: Vent grille / 6 mm gap behind the top fixed front (induction air) | D37: 1 | E37: pcs | F37: Island_2_Induction_750
A38: Electrical | B38: Induction power: dedicated circuit in floor conduit to the island | D38: 1 | E38: pcs | F38: Island
A39: Lighting | B39: Ch1 under-cabinet: 24 V COB LED strip 4000K 10 W/m + Al profile 16x7 with diffuser | D39: 1.81 | E39: m | F39: Lighting_LED
A40: Lighting | B40: Ch1 under-cabinet: 24 V LED driver 30 W | D40: 1 | E40: pcs | F40: Lighting_LED
A41: Lighting | B41: Ch2 toe-kick wall run: 24 V COB LED strip 4000K 10 W/m + Al profile 16x7 with diffuser | D41: 1.29 | E41: m | F41: Lighting_LED
...

Sheet Cut List
A1: Kitchen v2 - Cut List (all sizes in mm, finished size, no edge allowance)
A2: From build_kitchen_v2.py. PVC has no grain: parts may be rotated on the sheet. 'Notched' parts: cut the full rectangle, then the notch shown in the FreeCAD model.
A4: Ref # | B4: Module | C4: Part | D4: Qty | E4: Length | F4: Width | G4: Thickness | H4: Material | I4: Area m² | J4: Note | K4: On sheet(s)
A5: 1 | B5: Base_Racks_400 | C5: Back | D5: 1 | E5: 776 | F5: 400 | G5: 18 | H5: PVC board 18 mm | I5: =D5*E5*F5/1000000 -> 0.3104 | K5: A9
A6: 2 | B6: Base_Racks_400 | C6: Bottom | D6: 1 | E6: 574 | F6: 364 | G6: 18 | H6: PVC board 18 mm | I6: =D6*E6*F6/1000000 -> 0.208936 | K6: A11
A7: 3 | B7: Base_Racks_400 | C7: DrawerFront_1 | D7: 1 | E7: 397 | F7: 307.4 | G7: 18 | H7: PVC board 18 mm | I7: =D7*E7*F7/1000000 -> 0.1220378 | K7: A12
A8: 4 | B8: Base_Racks_400 | C8: DrawerFront_2 | D8: 1 | E8: 397 | F8: 268.6 | G8: 18 | H8: PVC board 18 mm | I8: =D8*E8*F8/1000000 -> 0.1066342 | K8: A12
A9: 5 | B9: Base_Racks_400 | C9: DrawerFront_3 | D9: 1 | E9: 397 | F9: 191 | G9: 18 | H9: PVC board 18 mm | I9: =D9*E9*F9/1000000 -> 0.075827 | K9: A12
A10: 6 | B10: Base_Racks_400 | C10: Kick_Back | D10: 1 | E10: 303 | F10: 73 | G10: 18 | H10: PVC board 18 mm | I10: =D10*E10*F10/1000000 -> 0.022119 | K10: A12
A11: 7 | B11: Base_Racks_400 | C11: Kick_DrawerFront | D11: 1 | E11: 397 | F11: 87 | G11: 18 | H11: PVC board 18 mm | I11: =D11*E11*F11/1000000 -> 0.034539 | K11: A12
A12: 8 | B12: Base_Racks_400 | C12: Kick_Inner_Front | D12: 1 | E12: 303 | F12: 73 | G12: 18 | H12: PVC board 18 mm | I12: =D12*E12*F12/1000000 -> 0.022119 | K12: A10
A13: 9 | B13: Base_Racks_400 | C13: Kick_Side_A | D13: 1 | E13: 400 | F13: 73 | G13: 18 | H13: PVC board 18 mm | I13: =D13*E13*F13/1000000 -> 0.0292 | K13: A9
A14: 10 | B14: Base_Racks_400 | C14: Kick_Side_B | D14: 1 | E14: 400 | F14: 73 | G14: 18 | H14: PVC board 18 mm | I14: =D14*E14*F14/1000000 -> 0.0292 | K14: A1
A15: 11 | B15: Base_Racks_400 | C15: Plinth_Back | D15: 1 | E15: 400 | F15: 100 | G15: 18 | H15: PVC board 18 mm | I15: =D15*E15*F15/1000000 -> 0.04 | K15: A12
A16: 12 | B16: Base_Racks_400 | C16: Plinth_Side_A | D16: 1 | E16: 454 | F16: 100 | G16: 18 | H16: PVC board 18 mm | I16: =D16*E16*F16/1000000 -> 0.0454 | K16: A10
... A90: 86 | B90: Island_3_Racks_450 | C90: Stretcher_Front | D90: 1 | E90: 414 | F90: 100 | G90: 18 | H90: PVC board 18 mm | I90: =D90*E90*F90/1000000 -> 0.0414 | K90: A12
A91: 87 | B91: Over_Ref_Cabinet | C91: Back | D91: 1 | E91: 950 | F91: 457 | G91: 18 | H91: PVC board 18 mm | I91: =D91*E91*F91/1000000 -> 0.43415 | J91: notched for pipe - see model | K91: A3
A92: 88 | B92: Over_Ref_Cabinet | C92: Bottom | D92: 1 | E92: 914 | F92: 748 | G92: 18 | H92: PVC board 18 mm | I92: =D92*E92*F92/1000000 -> 0.683672 | J92: notched for pipe - see model | K92: A4
A93: 89 | B93: Over_Ref_Cabinet | C93: Door_1 | D93: 1 | E93: 472 | F93: 454 | G93: 18 | H93: PVC board 18 mm | I93: =D93*E93*F93/1000000 -> 0.214288 | K93: A11
A94: 90 | B94: Over_Ref_Cabinet | C94: Door_2 | D94: 1 | E94: 472 | F94: 454 | G94: 18 | H94: PVC board 18 mm | I94: =D94*E94*F94/1000000 -> 0.214288 | K94: A12
A95: 91 | B95: Over_Ref_Cabinet | C95: Pipe_Chase_Front | D95: 1 | E95: 457 | F95: 122 | G95: 18 | H95: PVC board 18 mm | I95: =D95*E95*F95/1000000 -> 0.055754 | K95: A10
A96: 92 | B96: Over_Ref_Cabinet | C96: Pipe_Chase_Side | D96: 1 | E96: 457 | F96: 124 | G96: 18 | H96: PVC board 18 mm | I96: =D96*E96*F96/1000000 -> 0.056668 | K96: A11
A97: 93 | B97: Over_Ref_Cabinet | C97: Shelf_1 | D97: 1 | E97: 914 | F97: 710 | G97: 18 | H97: PVC board 18 mm | I97: =D97*E97*F97/1000000 -> 0.64894 | J97: notched for pipe - see model | K97: A5
A98: 94 | B98: Over_Ref_Cabinet | C98: Side_A | D98: 1 | E98: 748 | F98: 457 | G98: 18 | H98: PVC board 18 mm | I98: =D98*E98*F98/1000000 -> 0.341836 | J98: notched for pipe - see model | K98: A10
A99: 95 | B99: Over_Ref_Cabinet | C99: Side_B | D99: 1 | E99: 748 | F99: 457 | G99: 18 | H99: PVC board 18 mm | I99: =D99*E99*F99/1000000 -> 0.341836 | K99: A10
A100: 96 | B100: Over_Ref_Cabinet | C100: Top | D100: 1 | E100: 914 | F100: 748 | G100: 18 | H100: PVC board 18 mm | I100: =D100*E100*F100/1000000 -> 0.683672 | J100: notched for pipe - see model | K100: A5
A101: 97 | B101: Ref_Tower | C101: End_Panel_Ref | D101: 1 | E101: 2286 | F101: 784 | G101: 18 | H101: PVC board 18 mm | I101: =D101*E101*F101/1000000 -> 1.792224 | K101: A1
A102: 98 | B102: Ref_Tower | C102: Filler_Ref | D102: 1 | E102: 2286 | F102: 30 | G102: 18 | H102: PVC board 18 mm | I102: =D102*E102*F102/1000000 -> 0.06858 | K102: A1
A103: 99 | B103: Ref_Tower | C103: Tall_Panel | D103: 1 | E103: 2286 | F103: 784 | G103: 18 | H103: PVC board 18 mm | I103: =D103*E103*F103/1000000 -> 1.792224 | K103: A2
A104: 100 | B104: Scribe_Strips | C104: Crown_Ref | D104: 1 | E104: 1016 | F104: 50.8 | G104: 18 | H104: PVC board 18 mm | I104: =D104*E104*F104/1000000 -> 0.0516128 | K104: A3
A105: 101 | B105: Scribe_Strips | C105: Crown_Uppers | D105: 1 | E105: 1938 | F105: 50.8 | G105: 18 | H105: PVC board 18 mm | I105: =D105*E105*F105/1000000 -> 0.0984504 | K105: A1
A106: 102 | B106: Scribe_Strips | C106: Crown_Washer | D106: 1 | E106: 652.8 | F106: 50.8 | G106: 18 | H106: PVC board 18 mm | I106: =D106*E106*F106/1000000 -> 0.03316224 | K106: A8
A107: 103 | B107: Stove_Bay | C107: Stove_Platform_Riser | D107: 3 | E107: 609.6 | F107: 46 | G107: 18 | H107: PVC board 18 mm | I107: =D107*E107*F107/1000000 -> 0.0841248 | J107: under the platform top | K107: A8, A9
A108: 104 | B108: Stove_Bay | C108: Stove_Platform_Top | D108: 1 | E108: 609.6 | F108: 609.6 | G108: 18 | H108: PVC board 18 mm | I108: =D108*E108*F108/1000000 -> 0.37161216 | J108: platform 64 H total | K108: A11
A109: 105 | B109: Upper_400 | C109: Back | D109: 1 | E109: 914 | F109: 400 | G109: 18 | H109: PVC board 18 mm | I109: =D109*E109*F109/1000000 -> 0.3656 | K109: A4
A110: 106 | B110: Upper_400 | C110: Bottom | D110: 1 | E110: 364 | F110: 294 | G110: 18 | H110: PVC board 18 mm | I110: =D110*E110*F110/1000000 -> 0.107016 | K110: A12
A111: 107 | B111: Upper_400 | C111: Door_1 | D111: 1 | E111: 911 | F111: 397 | G111: 18 | H111: PVC board 18 mm | I111: =D111*E111*F111/1000000 -> 0.361667 | K111: A2
A112: 108 | B112: Upper_400 | C112: Shelf_1 | D112: 1 | E112: 364 | F112: 256 | G112: 18 | H112: PVC board 18 mm | I112: =D112*E112*F112/1000000 -> 0.093184 | K112: A3
A113: 109 | B113: Upper_400 | C113: Shelf_2 | D113: 1 | E113: 364 | F113: 256 | G113: 18 | H113: PVC board 18 mm | I113: =D113*E113*F113/1000000 -> 0.093184 | K113: A12
A114: 110 | B114: Upper_400 | C114: Side_A | D114: 1 | E114: 914 | F114: 294 | G114: 18 | H114: PVC board 18 mm | I114: =D114*E114*F114/1000000 -> 0.268716 | K114: A4
...

Sheet Fronts & Hinges
A1: Doors and drawer fronts
A2: Hinges: 35 mm cup, soft-close, clip-on. Rule used: door long side <= 900 mm -> 2 hinges, <= 1600 mm -> 3, longer -> 4 (typical hinge-maker guidance; check your hinge brand).
A4: Ref # | B4: Module | C4: Part | D4: Qty | E4: Long side | F4: Short side | G4: Type | H4: Hinges | I4: Handle / latch | J4: Front edge length m
A5: 3 | B5: Base_Racks_400 | C5: DrawerFront_1 | D5: 1 | E5: 397 | F5: 307.4 | G5: Drawer | H5: =IF(G5="Door",D5*IF(E5<=900,2,IF(E5<=1600,3,4)),0) -> 0 | I5: =IF(G5="Toe-kick drawer",0,D5) -> 1 | J5: =D5*2*(E5+F5)/1000 -> 1.4088
A6: 4 | B6: Base_Racks_400 | C6: DrawerFront_2 | D6: 1 | E6: 397 | F6: 268.6 | G6: Drawer | H6: =IF(G6="Door",D6*IF(E6<=900,2,IF(E6<=1600,3,4)),0) -> 0 | I6: =IF(G6="Toe-kick drawer",0,D6) -> 1 | J6: =D6*2*(E6+F6)/1000 -> 1.3312
A7: 5 | B7: Base_Racks_400 | C7: DrawerFront_3 | D7: 1 | E7: 397 | F7: 191 | G7: Drawer | H7: =IF(G7="Door",D7*IF(E7<=900,2,IF(E7<=1600,3,4)),0) -> 0 | I7: =IF(G7="Toe-kick drawer",0,D7) -> 1 | J7: =D7*2*(E7+F7)/1000 -> 1.176
A8: 7 | B8: Base_Racks_400 | C8: Kick_DrawerFront | D8: 1 | E8: 397 | F8: 87 | G8: Toe-kick drawer | H8: =IF(G8="Door",D8*IF(E8<=900,2,IF(E8<=1600,3,4)),0) -> 0 | I8: =IF(G8="Toe-kick drawer",0,D8) -> 0 | J8: =D8*2*(E8+F8)/1000 -> 0.968
A9: 19 | B9: Base_Sink_900 | C9: Door_1 | D9: 1 | E9: 773 | F9: 447 | G9: Door | H9: =IF(G9="Door",D9*IF(E9<=900,2,IF(E9<=1600,3,4)),0) -> 2 | I9: =IF(G9="Toe-kick drawer",0,D9) -> 1 | J9: =D9*2*(E9+F9)/1000 -> 2.44
A10: 20 | B10: Base_Sink_900 | C10: Door_2 | D10: 1 | E10: 773 | F10: 447 | G10: Door | H10: =IF(G10="Door",D10*IF(E10<=900,2,IF(E10<=1600,3,4)),0) -> 2 | I10: =IF(G10="Toe-kick drawer",0,D10) -> 1 | J10: =D10*2*(E10+F10)/1000 -> 2.44
A11: 22 | B11: Base_Sink_900 | C11: Kick_DrawerFront | D11: 1 | E11: 897 | F11: 87 | G11: Toe-kick drawer | H11: =IF(G11="Door",D11*IF(E11<=900,2,IF(E11<=1600,3,4)),0) -> 0 | I11: =IF(G11="Toe-kick drawer",0,D11) -> 0 | J11: =D11*2*(E11+F11)/1000 -> 1.968
A12: 38 | B12: Island_1_Racks_450 | C12: DrawerFront_1 | D12: 1 | E12: 447 | F12: 307.4 | G12: Drawer | H12: =IF(G12="Door",D12*IF(E12<=900,2,IF(E12<=1600,3,4)),0) -> 0 | I12: =IF(G12="Toe-kick drawer",0,D12) -> 1 | J12: =D12*2*(E12+F12)/1000 -> 1.5088
A13: 39 | B13: Island_1_Racks_450 | C13: DrawerFront_2 | D13: 1 | E13: 447 | F13: 268.6 | G13: Drawer | H13: =IF(G13="Door",D13*IF(E13<=900,2,IF(E13<=1600,3,4)),0) -> 0 | I13: =IF(G13="Toe-kick drawer",0,D13) -> 1 | J13: =D13*2*(E13+F13)/1000 -> 1.4312
A14: 40 | B14: Island_1_Racks_450 | C14: DrawerFront_3 | D14: 1 | E14: 447 | F14: 191 | G14: Drawer | H14: =IF(G14="Door",D14*IF(E14<=900,2,IF(E14<=1600,3,4)),0) -> 0 | I14: =IF(G14="Toe-kick drawer",0,D14) -> 1 | J14: =D14*2*(E14+F14)/1000 -> 1.276
A15: 42 | B15: Island_1_Racks_450 | C15: Kick_DrawerFront | D15: 1 | E15: 447 | F15: 87 | G15: Toe-kick drawer | H15: =IF(G15="Door",D15*IF(E15<=900,2,IF(E15<=1600,3,4)),0) -> 0 | I15: =IF(G15="Toe-kick drawer",0,D15) -> 0 | J15: =D15*2*(E15+F15)/1000 -> 1.068
A16: 55 | B16: Island_2_Induction_750 | C16: DrawerFront_1 | D16: 1 | E16: 747 | F16: 325 | G16: Drawer | H16: =IF(G16="Door",D16*IF(E16<=900,2,IF(E16<=1600,3,4)),0) -> 0 | I16: =IF(G16="Toe-kick drawer",0,D16) -> 1 | J16: =D16*2*(E16+F16)/1000 -> 2.144
... A31: 135 | B31: Upper_Sink_900 | C31: Door_2 | D31: 1 | E31: 911 | F31: 447 | G31: Door | H31: =IF(G31="Door",D31*IF(E31<=900,2,IF(E31<=1600,3,4)),0) -> 3 | I31: =IF(G31="Toe-kick drawer",0,D31) -> 1 | J31: =D31*2*(E31+F31)/1000 -> 2.716
C32: Totals | D32: =SUM(D5:D31) -> 27 | H32: =SUM(H5:H31) -> 25 | I32: =SUM(I5:I31) -> 22 | J32: =SUM(J5:J31) -> 49.2456

Sheet Sheet Layout
A1: Nesting on 4x8 sheets (x, y from the sheet corner, mm) - see kitchen_v2_cutting_diagram.pdf
A2: Sheet 2440 x 1220, 5 mm edge trim, 4 mm saw kerf, guillotine cuts.
A4: Sheet | B4: Material | C4: Ref # | D4: Module | E4: Part | F4: X | G4: Y | H4: Along 2440 | I4: Along 1220 | J4: Rotated
A5: A1 | B5: PVC board 18 mm | C5: 97 | D5: Ref_Tower | E5: End_Panel_Ref | F5: 5 | G5: 5 | H5: 2286 | I5: 784
A6: A1 | B6: PVC board 18 mm | C6: 63 | D6: Island_2_Induction_750 | E6: Plinth_Back | F6: 2295 | G6: 5 | H6: 100 | I6: 750 | J6: yes
A7: A1 | B7: PVC board 18 mm | C7: 98 | D7: Ref_Tower | E7: Filler_Ref | F7: 5 | G7: 793 | H7: 2286 | I7: 30
A8: A1 | B8: PVC board 18 mm | C8: 101 | D8: Scribe_Strips | E8: Crown_Uppers | F8: 5 | G8: 827 | H8: 1938 | I8: 50.8
A9: A1 | B9: PVC board 18 mm | C9: 65 | D9: Island_2_Induction_750 | E9: Plinth_Side_B | F9: 1947 | G9: 827 | H9: 454 | I9: 100
A10: A1 | B10: PVC board 18 mm | C10: 137 | D10: Upper_Sink_900 | E10: Side_B | F10: 5 | G10: 882 | H10: 914 | I10: 294
A11: A1 | B11: PVC board 18 mm | C11: 123 | D11: Upper_Over_Washer | E11: Door_1 | F11: 923 | G11: 882 | H11: 911 | I11: 323.4
A12: A1 | B12: PVC board 18 mm | C12: 81 | D12: Island_3_Racks_450 | E12: Plinth_Side_A | F12: 1947 | G12: 931 | H12: 454 | I12: 100
A13: A1 | B13: PVC board 18 mm | C13: 82 | D13: Island_3_Racks_450 | E13: Plinth_Side_B | F13: 1947 | G13: 1035 | H13: 454 | I13: 100
A14: A1 | B14: PVC board 18 mm | C14: 10 | D14: Base_Racks_400 | E14: Kick_Side_B | F14: 1947 | G14: 1139 | H14: 400 | I14: 73
A15: A2 | B15: PVC board 18 mm | C15: 99 | D15: Ref_Tower | E15: Tall_Panel | F15: 5 | G15: 5 | H15: 2286 | I15: 784
A16: A2 | B16: PVC board 18 mm | C16: 57 | D16: Island_2_Induction_750 | E16: DrawerFront_3 | F16: 2295 | G16: 5 | H16: 117 | I16: 747 | J16: yes
A17: A2 | B17: PVC board 18 mm | C17: 107 | D17: Upper_400 | E17: Door_1 | F17: 5 | G17: 793 | H17: 911 | I17: 397
A18: A2 | B18: PVC board 18 mm | C18: 124 | D18: Upper_Over_Washer | E18: Door_2 | F18: 920 | G18: 793 | H18: 911 | I18: 323.4
A19: A2 | B19: PVC board 18 mm | C19: 117 | D19: Upper_Hood_620 | E19: Shelf_2 | F19: 1835 | G19: 793 | H19: 584 | I19: 224
A20: A2 | B20: PVC board 18 mm | C20: 27 | D20: Base_Sink_900 | E20: Plinth_Side_A | F20: 1835 | G20: 1021 | H20: 454 | I20: 100
A21: A2 | B21: PVC board 18 mm | C21: 22 | D21: Base_Sink_900 | E21: Kick_DrawerFront | F21: 920 | G21: 1120 | H21: 897 | I21: 87
A22: A2 | B22: PVC board 18 mm | C22: 76 | D22: Island_3_Racks_450 | E22: Kick_DrawerFront | F22: 1835 | G22: 1125 | H22: 447 | I22: 87
A23: A3 | B23: PVC board 18 mm | C23: 33 | D23: Island | E23: Island_Back_Panel (seating side) | F23: 5 | G23: 5 | H23: 1650 | I23: 876
A24: A3 | B24: PVC board 18 mm | C24: 87 | D24: Over_Ref_Cabinet | E24: Back | F24: 1659 | G24: 5 | H24: 457 | I24: 950 | J24: yes
A25: A3 | B25: PVC board 18 mm | C25: 111 | D25: Upper_400 | E25: Side_B | F25: 2120 | G25: 5 | H25: 294 | I25: 914 | J25: yes
A26: A3 | B26: PVC board 18 mm | C26: 100 | D26: Scribe_Strips | E26: Crown_Ref | F26: 5 | G26: 885 | H26: 1016 | I26: 50.8
A27: A3 | B27: PVC board 18 mm | C27: 122 | D27: Upper_Over_Washer | E27: Bottom | F27: 1025 | G27: 885 | H27: 616.8 | I27: 294
A28: A3 | B28: PVC board 18 mm | C28: 127 | D28: Upper_Over_Washer | E28: Shelf_1 | F28: 5 | G28: 940 | H28: 616.8 | I28: 256
A29: A3 | B29: PVC board 18 mm | C29: 108 | D29: Upper_400 | E29: Shelf_1 | F29: 626 | G29: 940 | H29: 364 | I29: 256
A30: A3 | B30: PVC board 18 mm | C30: 28 | D30: Base_Sink_900 | E30: Plinth_Side_B | F30: 1659 | G30: 959 | H30: 454 | I30: 100
A31: A3 | B31: PVC board 18 mm | C31: 47 | D31: Island_1_Racks_450 | E31: Plinth_Side_A | F31: 1659 | G31: 1063 | H31: 454 | I31: 100
A32: A4 | B32: PVC board 18 mm | C32: 132 | D32: Upper_Sink_900 | E32: Back | F32: 5 | G32: 5 | H32: 914 | I32: 900
A33: A4 | B33: PVC board 18 mm | C33: 88 | D33: Over_Ref_Cabinet | E33: Bottom | F33: 923 | G33: 5 | H33: 914 | I33: 748
A34: A4 | B34: PVC board 18 mm | C34: 134 | D34: Upper_Sink_900 | E34: Door_1 | F34: 1841 | G34: 5 | H34: 447 | I34: 911 | J34: yes
A35: A4 | B35: PVC board 18 mm | C35: 26 | D35: Base_Sink_900 | E35: Plinth_Back | F35: 2292 | G35: 5 | H35: 100 | I35: 900 | J35: yes
A36: A4 | B36: PVC board 18 mm | C36: 105 | D36: Upper_400 | E36: Back | F36: 923 | G36: 757 | H36: 914 | I36: 400
A37: A4 | B37: PVC board 18 mm | C37: 110 | D37: Upper_400 | E37: Side_A | F37: 5 | G37: 909 | H37: 914 | I37: 294
A38: A4 | B38: PVC board 18 mm | C38: 114 | D38: Upper_Hood_620 | E38: Bottom | F38: 1841 | G38: 920 | H38: 584 | I38: 294
A39: A5 | B39: PVC board 18 mm | C39: 96 | D39: Over_Ref_Cabinet | E39: Top | F39: 5 | G39: 5 | H39: 914 | I39: 748
A40: A5 | B40: PVC board 18 mm | C40: 93 | D40: Over_Ref_Cabinet | E40: Shelf_1 | F40: 923 | G40: 5 | H40: 914 | I40: 710
A41: A5 | B41: PVC board 18 mm | C41: 135 | D41: Upper_Sink_900 | E41: Door_2 | F41: 1841 | G41: 5 | H41: 447 | I41: 911 | J41: yes
...
