Workbook

Sheet Summary
A1: Aluminium kitchen - cut list & materials summary
A2: Basic materials: 2x1 tube, 4 mm cladding, profile, profile with handle. Blue = from the cutting plan (re-run make_kitchen_alu_cutlist.py after model changes).
A4: Item | B4: Value | C4: Unit | D4: Basis
A5: 2x1 pieces | B5: =SUMIFS('Cut List'!$E$5:$E$302,'Cut List'!$D$5:$D$302,"2x1") -> 272 | C5: pcs | D5: Cut List
A6: 2x1 total length | B6: =SUMIFS('Cut List'!$J$5:$J$302,'Cut List'!$D$5:$D$302,"2x1") -> 149.6747 | C6: m | D6: Cut List
A7: 2x1 stock bars | B7: 24 | C7: bars | D7: Bar Plan (6.40 m bars)
A8: 2x1 yield | B8: =B6/(B7*6.4) -> 0.97444466 | C8: % | D8: cut length / stock length
A9: Profile pieces | B9: =SUMIFS('Cut List'!$E$5:$E$302,'Cut List'!$D$5:$D$302,"Profile") -> 86 | C9: pcs | D9: Cut List
A10: Profile total length | B10: =SUMIFS('Cut List'!$J$5:$J$302,'Cut List'!$D$5:$D$302,"Profile") -> 36.9766 | C10: m | D10: Cut List
A11: Profile stock bars | B11: 6 | C11: bars | D11: Bar Plan (6.40 m bars)
A12: Profile yield | B12: =B10/(B11*6.4) -> 0.96293229 | C12: % | D12: cut length / stock length
A13: Profile with handle pieces | B13: =SUMIFS('Cut List'!$E$5:$E$302,'Cut List'!$D$5:$D$302,"Profile with handle") -> 22 | C13: pcs | D13: Cut List
A14: Profile with handle total length | B14: =SUMIFS('Cut List'!$J$5:$J$302,'Cut List'!$D$5:$D$302,"Profile with handle") -> 10.6478 | C14: m | D14: Cut List
A15: Profile with handle stock bars | B15: 2 | C15: bars | D15: Bar Plan (6.40 m bars)
A16: Profile with handle yield | B16: =B14/(B15*6.4) -> 0.83185937 | C16: % | D16: cut length / stock length
A17: Cladding pieces | B17: =SUMIFS('Cut List'!$E$5:$E$302,'Cut List'!$D$5:$D$302,"Cladding") -> 117 | C17: pcs | D17: Cut List
A18: Cladding part area | B18: =SUMIFS('Cut List'!$K$5:$K$302,'Cut List'!$D$5:$D$302,"Cladding") -> 34.56867 | C18: m² | D18: Cut List
A19: Cladding sheets (4x8) | B19: 13 | C19: sheets | D19: Cladding Layout / PDF
A20: Cladding yield | B20: =B18/(B19*2.9768) -> 0.89328421 | C20: % | D20: part area / sheet area
A21: Countertop pieces | B21: =SUMIFS('Cut List'!$E$5:$E$302,'Cut List'!$D$5:$D$302,"Countertop") -> 3 | C21: pcs | D21: fabricator templates

Sheet Materials
A1: List of materials - aluminium
A2: Black qty = formula; blue = count from the model or a rule of thumb (see Basis). Fill unit prices in the yellow column; the total is at the bottom.
A4: Category | B4: Item | C4: Specification | D4: Qty | E4: Unit | F4: Basis / note | G4: Unit price | H4: Amount
A5: Aluminium | B5: 2x1 | C5: 1" x 2" aluminium tube (25.4 x 50.8), 6.40 m bars | D5: =Summary!B7+2 -> 26 | E5: bars | F5: Bar Plan + 2 spare for mis-cuts; offcuts cover cleats | H5: =D5*G5 -> 0
A6: Aluminium | B6: Profile | C6: cabinet door / front frame profile (20 face x 20 deep, with insert groove), 6.40 m bars | D6: =Summary!B11+1 -> 7 | E6: bars | F6: Bar Plan + 1 spare for mis-cuts; offcuts cover cleats | H6: =D6*G6 -> 0
A7: Aluminium | B7: Profile with handle | C7: profile with integrated handle (45 face), 6.40 m bars | D7: =Summary!B15+1 -> 3 | E7: bars | F7: Bar Plan + 1 spare for mis-cuts; offcuts cover cleats | H7: =D7*G7 -> 0
A8: Aluminium | B8: Cladding | C8: aluminium cladding sheet 4 mm, 4x8 ft | D8: =Summary!B19+1 -> 14 | E8: sheets | F8: Cladding Layout + 1 spare | H8: =D8*G8 -> 0
A9: Countertop | B9: Countertop - Island | C9: 1825 x 968 x 38, Countertop (cooktop cut-out 700x400) | D9: 1 | E9: pc | F9: fabricator measures on site | H9: =D9*G9 -> 0
A10: Countertop | B10: Countertop - Sink_Counter | C10: 1270 x 635 x 38, Countertop (sink cut-out 770x420) | D10: 1 | E10: pc | F10: fabricator measures on site | H10: =D10*G10 -> 0
A11: Countertop | B11: Countertop - Washer_Bay | C11: 678 x 635 x 38, Countertop (corner notch 153x153 for pipe) | D11: 1 | E11: pc | F11: fabricator measures on site | H11: =D11*G11 -> 0
A12: Fasteners | B12: Blind (pop) rivets 4 mm (5/32") x 12 - frame joints | C12: aluminium | D12: =CEILING(4*Summary!B5,100) -> 1100 | E12: pcs | F12: 4 per 2x1 piece (2 per end) | H12: =D12*G12 -> 0
A13: Fasteners | B13: Rivets / self-drilling screws - cladding to frame | C13: every ~200 mm | D13: 1300 | E13: pcs | F13: cladding edge length 257 m / 0.2 | H13: =D13*G13 -> 0
A14: Fasteners | B14: Internal corner cleats (1" aluminium angle ~40 mm, or 2x1 offcuts) | C14: frame joints | D14: =CEILING(2*Summary!B5,10) -> 550 | E14: pcs | F14: 2 per 2x1 piece | H14: =D14*G14 -> 0
A15: Fasteners | B15: Panel adhesive / VHB tape for cladding (keeps panels flat) | D15: 257 | E15: m | F15: cladding edge length | H15: =D15*G15 -> 0
A16: Wall mount | B16: Masonry anchors 8 mm through the 2x1 back rails | D16: 38 | E16: pcs | F16: 5 wall cabinets x 4 + 5 base x 2 + 4 framed panels x 2 | H16: =D16*G16 -> 0
A17: Finishing | B17: Neutral-cure silicone, clear | C17: sink, counter joints, backsplash | D17: 3 | E17: tubes | F17: rule of thumb | H17: =D17*G17 -> 0
A18: Racks & runners | B18: Toe-kick drawer runner pair 400 mm, low profile, push-to-open | D18: 5 | E18: pcs | F18: Base_Racks_400, Base_Sink_870, Island_1_Racks_473, Island_2_Induction_773, Island_3_Racks_473 | H18: =D18*G18 -> 0
A19: Racks & runners | B19: Under-sink pull-out tray (door-mounted cabinet) | C19: 786 W x 450 D x 120 H | D19: 1 | E19: pcs | F19: Base_Sink_870 | H19: =D19*G19 -> 0
A20: Racks & runners | B20: Full-extension soft-close runner pair, 450 mm | D20: 1 | E20: pcs | F20: Base_Sink_870 | H20: =D20*G20 -> 0
A21: Racks & runners | B21: Pot / pan basket (350 cabinet size, 341 clear, 500 runners) | C21: 316 W x 500 D x 200 H | D21: 1 | E21: pcs | F21: Base_Racks_400 | H21: =D21*G21 -> 0
A22: Racks & runners | B22: Full-extension soft-close runner pair, 500 mm | D22: 11 | E22: pcs | F22: Base_Racks_400, Island_1_Racks_473, Island_2_Induction_773, Island_3_Racks_473 | H22: =D22*G22 -> 0
A23: Racks & runners | B23: Bowl + plate basket (350 cabinet size, 341 clear, 500 runners) | C23: 316 W x 500 D x 150 H | D23: 1 | E23: pcs | F23: Base_Racks_400 | H23: =D23*G23 -> 0
A24: Racks & runners | B24: Cutlery / utensil tray (350 cabinet size, 341 clear, 500 runners) | C24: 316 W x 500 D x 70 H | D24: 1 | E24: pcs | F24: Base_Racks_400 | H24: =D24*G24 -> 0
A25: Fittings | B25: Stove levelling feet: raise ~9 mm so the cooktop meets the counter (platform 54.8) | D25: 1 | E25: pcs | F25: Stove_Bay | H25: =D25*G25 -> 0
A26: Appliance fit | B26: Flat duct 204x60 + 150 round-to-flat adapter, up the cabinet back to the ceiling (cut-out in the cabinet top) | D26: 1 | E26: pcs | F26: Upper_Hood_620 | H26: =D26*G26 -> 0
A27: Appliance fit | B27: Built-in telescopic range hood 60 cm (body <= 561 W), ducted, 150 outlet, fixed to the bottom side rails | C27: 560 W x 280 D x 180 H | D27: 1 | E27: pcs | F27: Upper_Hood_620 | H27: =D27*G27 -> 0
A28: Finishing | B28: Paint / wrap the exposed pipe (counter -> wall cabinet) to match the backsplash | C28: 458 H section | D28: 1 | E28: lot | F28: Washer_Bay | H28: =D28*G28 -> 0
A29: Racks & runners | B29: Dish drainer drip tray | C29: 801 W x 245 D x 25 H | D29: 1 | E29: pcs | F29: Upper_Sink_870 | H29: =D29*G29 -> 0
A30: Racks & runners | B30: Dish drainer, plate tier (870 cabinet) | C30: 801 W x 245 D x 120 H | D30: 1 | E30: pcs | F30: Upper_Sink_870 | H30: =D30*G30 -> 0
A31: Racks & runners | B31: Dish drainer, cup / bowl tier (870 cabinet) | C31: 801 W x 245 D x 80 H | D31: 1 | E31: pcs | F31: Upper_Sink_870 | H31: =D31*G31 -> 0
A32: Racks & runners | B32: Pot / pan basket (450 cabinet size, 414 clear, 500 runners) | C32: 389 W x 500 D x 200 H | D32: 2 | E32: pcs | F32: Island_1_Racks_473, Island_3_Racks_473 | H32: =D32*G32 -> 0
A33: Racks & runners | B33: Bowl + plate basket (450 cabinet size, 414 clear, 500 runners) | C33: 389 W x 500 D x 150 H | D33: 2 | E33: pcs | F33: Island_1_Racks_473, Island_3_Racks_473 | H33: =D33*G33 -> 0
A34: Racks & runners | B34: Cutlery / utensil tray (450 cabinet size, 414 clear, 500 runners) | C34: 389 W x 500 D x 70 H | D34: 2 | E34: pcs | F34: Island_1_Racks_473, Island_3_Racks_473 | H34: =D34*G34 -> 0
A35: Racks & runners | B35: Deep pot basket (750 cabinet size, 714 clear, 500 runners) | C35: 689 W x 500 D x 250 H | D35: 1 | E35: pcs | F35: Island_2_Induction_773 | H35: =D35*G35 -> 0
A36: Racks & runners | B36: Pot / pan basket (750 cabinet size, 714 clear, 500 runners) | C36: 689 W x 500 D x 200 H | D36: 1 | E36: pcs | F36: Island_2_Induction_773 | H36: =D36*G36 -> 0
A37: Appliance fit | B37: Vent grille / 6 mm gap behind the top fixed front (induction air) | D37: 1 | E37: pcs | F37: Island_2_Induction_773 | H37: =D37*G37 -> 0
A38: Electrical | B38: Induction power: dedicated circuit in floor conduit to the island | D38: 1 | E38: pcs | F38: Island | H38: =D38*G38 -> 0
A39: Lighting | B39: Ch1 under-cabinet: 24 V COB LED strip 4000K 10 W/m + Al profile 16x7 with diffuser | D39: 1.71 | E39: m | F39: Lighting_LED | H39: =D39*G39 -> 0
A40: Lighting | B40: Ch1 under-cabinet: 24 V LED driver 30 W | D40: 1 | E40: pcs | F40: Lighting_LED | H40: =D40*G40 -> 0
A41: Lighting | B41: Ch2 toe-kick wall run: 24 V COB LED strip 4000K 10 W/m + Al profile 16x7 with diffuser | D41: 1.26 | E41: m | F41: Lighting_LED | H41: =D41*G41 -> 0
...

Sheet Cut List
A1: Aluminium kitchen - Cut List (mm)
A2: Bars at cut length (mitred profiles: long point, see Note). Bar / sheet: T = 2x1, P = profile, H = profile with handle, C = cladding sheet. 'see model' = notch / cut-back shown in FreeCAD.
A4: Ref # | B4: Module | C4: Part | D4: Material | E4: Qty | F4: Length | G4: Width | H4: Note | I4: Bar / sheet | J4: Total m | K4: Area m²
A5: 1 | B5: Base_Racks_400 | C5: Kick_Back | D5: 2x1 | E5: 1 | F5: 265.4 | I5: T23 | J5: =E5*F5/1000 -> 0.2654
A6: 2 | B6: Base_Racks_400 | C6: Kick_Inner_Front | D6: 2x1 | E6: 1 | F6: 265.4 | I6: T24 | J6: =E6*F6/1000 -> 0.2654
A7: 3 | B7: Base_Racks_400 | C7: Kick_Side | D7: 2x1 | E7: 2 | F7: 400 | I7: T20 | J7: =E7*F7/1000 -> 0.8
A8: 4 | B8: Base_Racks_400 | C8: Plinth_Leg_Back | D8: 2x1 | E8: 2 | F8: 100 | I8: T10, T6 | J8: =E8*F8/1000 -> 0.2
A9: 5 | B9: Base_Racks_400 | C9: Plinth_Leg_Front | D9: 2x1 | E9: 2 | F9: 100 | I9: T11, T21 | J9: =E9*F9/1000 -> 0.2
A10: 6 | B10: Base_Racks_400 | C10: Plinth_Rail_Back | D10: 2x1 | E10: 1 | F10: 341.2 | I10: T4 | J10: =E10*F10/1000 -> 0.3412
A11: 7 | B11: Base_Racks_400 | C11: Plinth_Rail_Side | D11: 2x1 | E11: 2 | F11: 368.4 | I11: T15, T21 | J11: =E11*F11/1000 -> 0.7368
A12: 8 | B12: Base_Racks_400 | C12: Post_Back | D12: 2x1 | E12: 2 | F12: 772 | I12: T9 | J12: =E12*F12/1000 -> 1.544
A13: 9 | B13: Base_Racks_400 | C13: Post_Front | D13: 2x1 | E13: 2 | F13: 772 | I13: T9 | J13: =E13*F13/1000 -> 1.544
A14: 10 | B14: Base_Racks_400 | C14: Rail_Back_Bottom | D14: 2x1 | E14: 1 | F14: 341.2 | I14: T21 | J14: =E14*F14/1000 -> 0.3412
A15: 11 | B15: Base_Racks_400 | C15: Rail_Back_Top | D15: 2x1 | E15: 1 | F15: 341.2 | I15: T21 | J15: =E15*F15/1000 -> 0.3412
A16: 12 | B16: Base_Racks_400 | C16: Rail_Front_Bottom | D16: 2x1 | E16: 1 | F16: 341.2 | I16: T21 | J16: =E16*F16/1000 -> 0.3412
... A90: 86 | B90: Over_Ref_Cabinet | C90: Post_Front | D90: 2x1 | E90: 2 | F90: 449 | I90: T19 | J90: =E90*F90/1000 -> 0.898
A91: 87 | B91: Over_Ref_Cabinet | C91: Rail_Back_Bottom | D91: 2x1 | E91: 1 | F91: 891.2 | H91: cut back at pipe chase - see model | I91: T2 | J91: =E91*F91/1000 -> 0.8912
A92: 88 | B92: Over_Ref_Cabinet | C92: Rail_Back_Top | D92: 2x1 | E92: 1 | F92: 891.2 | H92: cut back at pipe chase - see model | I92: T3 | J92: =E92*F92/1000 -> 0.8912
A93: 89 | B93: Over_Ref_Cabinet | C93: Rail_Front_Bottom | D93: 2x1 | E93: 1 | F93: 891.2 | I93: T6 | J93: =E93*F93/1000 -> 0.8912
A94: 90 | B94: Over_Ref_Cabinet | C94: Rail_Front_Top | D94: 2x1 | E94: 1 | F94: 891.2 | I94: T6 | J94: =E94*F94/1000 -> 0.8912
A95: 91 | B95: Over_Ref_Cabinet | C95: Rail_Side_Bottom | D95: 2x1 | E95: 1 | F95: 658.4 | I95: T13 | J95: =E95*F95/1000 -> 0.6584
A96: 92 | B96: Over_Ref_Cabinet | C96: Rail_Side_Bottom | D96: 2x1 | E96: 1 | F96: 658.4 | H96: cut back at pipe chase - see model | I96: T13 | J96: =E96*F96/1000 -> 0.6584
A97: 93 | B97: Over_Ref_Cabinet | C97: Rail_Side_Top | D97: 2x1 | E97: 1 | F97: 658.4 | I97: T13 | J97: =E97*F97/1000 -> 0.6584
A98: 94 | B98: Over_Ref_Cabinet | C98: Rail_Side_Top | D98: 2x1 | E98: 1 | F98: 658.4 | H98: cut back at pipe chase - see model | I98: T13 | J98: =E98*F98/1000 -> 0.6584
A99: 95 | B99: Over_Ref_Cabinet | C99: Shelf_Front_Rail | D99: 2x1 | E99: 1 | F99: 840.4 | I99: T8 | J99: =E99*F99/1000 -> 0.8404
A100: 96 | B100: Over_Ref_Cabinet | C100: Shelf_Support | D100: 2x1 | E100: 1 | F100: 760 | I100: T1 | J100: =E100*F100/1000 -> 0.76
A101: 97 | B101: Over_Ref_Cabinet | C101: Shelf_Support | D101: 2x1 | E101: 1 | F101: 760 | H101: cut back at pipe chase - see model | I101: T12 | J101: =E101*F101/1000 -> 0.76
A102: 98 | B102: Ref_Tower | C102: End_Panel_Ref_Rail | D102: 2x1 | E102: 10 | F102: 315.8 | I102: T22 | J102: =E102*F102/1000 -> 3.158
A103: 99 | B103: Ref_Tower | C103: End_Panel_Ref_Stud | D103: 2x1 | E103: 3 | F103: 2286 | I103: T1, T2 | J103: =E103*F103/1000 -> 6.858
A104: 100 | B104: Ref_Tower | C104: Filler_Ref_Post | D104: 2x1 | E104: 1 | F104: 2286 | I104: T2 | J104: =E104*F104/1000 -> 2.286
A105: 101 | B105: Ref_Tower | C105: Tall_Panel_Rail | D105: 2x1 | E105: 10 | F105: 315.8 | I105: T22, T23 | J105: =E105*F105/1000 -> 3.158
A106: 102 | B106: Ref_Tower | C106: Tall_Panel_Stud | D106: 2x1 | E106: 3 | F106: 2286 | I106: T3, T4 | J106: =E106*F106/1000 -> 6.858
A107: 103 | B107: Scribe_Strips | C107: Crown_Ref_Ledger | D107: 2x1 | E107: 1 | F107: 1038.8 | I107: T1 | J107: =E107*F107/1000 -> 1.0388
A108: 104 | B108: Scribe_Strips | C108: Crown_Uppers_Ledger | D108: 2x1 | E108: 1 | F108: 1919.4 | I108: T4 | J108: =E108*F108/1000 -> 1.9194
A109: 105 | B109: Scribe_Strips | C109: Crown_Washer_Ledger | D109: 2x1 | E109: 1 | F109: 648.6 | I109: T13 | J109: =E109*F109/1000 -> 0.6486
A110: 106 | B110: Stove_Bay | C110: Platform_Cross | D110: 2x1 | E110: 3 | F110: 558.8 | I110: T15 | J110: =E110*F110/1000 -> 1.6764
A111: 107 | B111: Stove_Bay | C111: Platform_Rail_Back | D111: 2x1 | E111: 1 | F111: 609.6 | I111: T14 | J111: =E111*F111/1000 -> 0.6096
A112: 108 | B112: Stove_Bay | C112: Platform_Rail_Front | D112: 2x1 | E112: 1 | F112: 609.6 | I112: T14 | J112: =E112*F112/1000 -> 0.6096
A113: 109 | B113: Upper_400 | C113: Post_Back | D113: 2x1 | E113: 2 | F113: 906 | I113: T2, T3 | J113: =E113*F113/1000 -> 1.812
... A131: 127 | B131: Upper_Over_Washer | C131: Post_Front | D131: 2x1 | E131: 2 | F131: 906 | I131: T5 | J131: =E131*F131/1000 -> 1.812
...

Sheet Bar Plan
A1: Bar cutting plan - 2x1, profile, profile with handle
A2: First-fit decreasing. 10 mm squared off each bar end, 3 mm blade. Cuts as 'Ref #: length'. Keep offcuts > 300 mm for corner cleats and repairs.
A4: Bar | B4: Material | C4: Stock mm | D4: Pieces | E4: Cuts (Ref #: length) | F4: Used mm | G4: Offcut mm
A5: T1 | B5: 2x1 | C5: 6400 | D5: 4 | E5: 99: 2286, 99: 2286, 103: 1038.8, 96: 760 | F5: 6379.8 | G5: =C5-F5-20 -> 0.2
A6: T2 | B6: 2x1 | C6: 6400 | D6: 4 | E6: 99: 2286, 100: 2286, 109: 906, 87: 891.2 | F6: 6378.2 | G6: =C6-F6-20 -> 1.8
A7: T3 | B7: 2x1 | C7: 6400 | D7: 4 | E7: 102: 2286, 102: 2286, 109: 906, 88: 891.2 | F7: 6378.2 | G7: =C7-F7-20 -> 1.8
A8: T4 | B8: 2x1 | C8: 6400 | D8: 5 | E8: 102: 2286, 104: 1919.4, 110: 906, 110: 906, 6: 341.2 | F8: 6370.6 | G8: =C8-F8-20 -> 9.4
A9: T5 | B9: 2x1 | C9: 6400 | D9: 7 | E9: 125: 906, 126: 906, 127: 906, 127: 906, 138: 906, 138: 906, 139: 906 | F9: 6360 | G9: =C9-F9-20 -> 20
A10: T6 | B10: 2x1 | C10: 6400 | D10: 8 | E10: 139: 906, 89: 891.2, 90: 891.2, 33: 876, 33: 876, 33: 876, 33: 876, 4: 100 | F10: 6313.4 | G10: =C10-F10-20 -> 66.6
A11: T7 | B11: 2x1 | C11: 6400 | D11: 8 | E11: 35: 876, 35: 876, 35: 876, 35: 876, 148: 876, 148: 876, 150: 876, 115: 204.4 | F11: 6357.4 | G11: =C11-F11-20 -> 22.6
A12: T8 | B12: 2x1 | C12: 6400 | D12: 8 | E12: 150: 876, 95: 840.4, 22: 811.2, 26: 811.2, 27: 811.2, 28: 811.2, 29: 811.2, 120: 561.2 | F12: 6354.6 | G12: =C12-F12-20 -> 25.4
A13: T9 | B13: 2x1 | C13: 6400 | D13: 8 | E13: 140: 811.2, 141: 811.2, 142: 811.2, 143: 811.2, 8: 772, 8: 772, 9: 772, 9: 772 | F13: 6353.8 | G13: =C13-F13-20 -> 26.2
A14: T10 | B14: 2x1 | C14: 6400 | D14: 9 | E14: 24: 772, 24: 772, 25: 772, 25: 772, 43: 772, 43: 772, 44: 772, 44: 772, 4: 100 | F14: 6300 | G14: =C14-F14-20 -> 80
A15: T11 | B15: 2x1 | C15: 6400 | D15: 9 | E15: 59: 772, 59: 772, 60: 772, 60: 772, 75: 772, 75: 772, 76: 772, 76: 772, 5: 100 | F15: 6300 | G15: =C15-F15-20 -> 80
A16: T12 | B16: 2x1 | C16: 6400 | D16: 9 | E16: 97: 760, 17: 735.4, 18: 735.4, 57: 714, 61: 714, 62: 714, 63: 714, 64: 714, 34: 541.8 | F16: 6366.6 | G16: =C16-F16-20 -> 13.4
... A36: H2 | B36: Profile with handle | C36: 6400 | D36: 11 | E36: 198: 469.8, 195: 432, 195: 432, 203: 432, 203: 432, 194: 397, 194: 397, 194: 397, 200: 397, 202: 321.3, 202: 321.3 | F36: 4458.4 | G36: =C36-F36-20 -> 1921.6

Sheet Cladding Layout
A1: Cladding nesting on 4x8 sheets (x, y from the sheet corner, mm) - see kitchen_alu_cutting_diagram.pdf
A2: Sheet 2440 x 1220, 5 mm edge trim, 4 mm blade, guillotine cuts.
A4: Sheet | B4: Ref # | C4: Module | D4: Part | E4: X | F4: Y | G4: Along 2440 | H4: Along 1220 | I4: Rotated
A5: C1 | B5: 261 | C5: Ref_Tower | D5: End_Panel_Ref_Clad | E5: 5 | F5: 5 | G5: 2286 | H5: 784
A6: C1 | B6: 239 | C6: Island_2_Induction_773 | D6: Plinth_Back_Clad | E6: 2295 | F6: 5 | G6: 100 | H6: 764.8 | I6: yes
A7: C1 | B7: 262 | C7: Ref_Tower | D7: Filler_Ref_Clad | E7: 5 | F7: 793 | G7: 2286 | H7: 30
A8: C1 | B8: 265 | C8: Scribe_Strips | D8: Crown_Uppers_Clad | E8: 5 | F8: 827 | G8: 1919.4 | H8: 50.8
A9: C1 | B9: 240 | C9: Island_2_Induction_773 | D9: Plinth_Side_Clad | E9: 1928 | F9: 827 | G9: 474 | H9: 100
A10: C1 | B10: 287 | C10: Upper_Over_Washer | D10: Side_Clad | E10: 5 | F10: 882 | G10: 914 | H10: 310
A11: C1 | B11: 292 | C11: Upper_Sink_870 | D11: Side_Clad | E11: 923 | F11: 882 | G11: 914 | H11: 310
A12: C1 | B12: 250 | C12: Island_3_Racks_473 | D12: Plinth_Side_Clad | E12: 1928 | F12: 931 | G12: 474 | H12: 100
A13: C1 | B13: 250 | C13: Island_3_Racks_473 | D13: Plinth_Side_Clad | E13: 1928 | F13: 1035 | G13: 474 | H13: 100
A14: C1 | B14: 229 | C14: Island_1_Racks_473 | D14: Kick_Front_Insert | E14: 1928 | F14: 1139 | G14: 445.8 | H14: 63
A15: C2 | B15: 263 | C15: Ref_Tower | D15: Tall_Panel_Clad | E15: 5 | F15: 5 | G15: 2286 | H15: 784
A16: C2 | B16: 219 | C16: Base_Sink_870 | D16: Plinth_Side_Clad | E16: 2295 | F16: 5 | G16: 100 | H16: 474 | I16: yes
A17: C2 | B17: 216 | C17: Base_Sink_870 | D17: Kick_Bottom_Clad | E17: 5 | F17: 793 | G17: 786.2 | H17: 400
A18: C2 | B18: 215 | C18: Base_Sink_870 | D18: Door_Insert | E18: 795 | F18: 793 | G18: 724 | H18: 408
A19: C2 | B19: 237 | C19: Island_2_Induction_773 | D19: Kick_Bottom_Clad | E19: 1523 | F19: 793 | G19: 689 | H19: 400
A20: C3 | B20: 221 | C20: Island | D20: Island_Back_Panel_Clad | E20: 5 | F20: 5 | G20: 1718.4 | H20: 876
A21: C3 | B21: 280 | C21: Upper_Over_Washer | D21: Back_Clad | E21: 1727 | F21: 5 | G21: 640.6 | H21: 914 | I21: yes
A22: C3 | B22: 264 | C22: Scribe_Strips | D22: Crown_Ref_Clad | E22: 5 | F22: 885 | G22: 1038.8 | H22: 50.8
A23: C3 | B23: 278 | C23: Upper_Hood_620 | D23: Side_Clad | E23: 1048 | F23: 885 | G23: 672 | H23: 310
A24: C3 | B24: 285 | C24: Upper_Over_Washer | D24: Shelf | E24: 1727 | F24: 923 | G24: 589.8 | H24: 286
A25: C3 | B25: 283 | C25: Upper_Over_Washer | D25: Pipe_Chase_Front_Clad | E25: 5 | F25: 940 | G25: 914 | H25: 153.4
A26: C3 | B26: 218 | C26: Base_Sink_870 | D26: Plinth_Back_Clad | E26: 5 | F26: 1097 | G26: 862 | H26: 100
A27: C4 | B27: 221 | C27: Island | D27: Island_Back_Panel_Clad | E27: 5 | F27: 5 | G27: 1718.4 | H27: 876
A28: C4 | B28: 292 | C28: Upper_Sink_870 | D28: Side_Clad | E28: 1727 | F28: 5 | G28: 310 | H28: 914 | I28: yes
A29: C4 | B29: 270 | C29: Upper_400 | D29: Door_Insert | E29: 2041 | F29: 5 | G29: 373 | H29: 862 | I29: yes
A30: C4 | B30: 269 | C30: Upper_400 | D30: Bottom_Clad | E30: 2041 | F30: 871 | G30: 392 | H30: 306
A31: C4 | B31: 286 | C31: Upper_Over_Washer | D31: Side_Clad | E31: 5 | F31: 885 | G31: 914 | H31: 310
A32: C4 | B32: 236 | C32: Island_2_Induction_773 | D32: DrawerFront_Insert | E32: 923 | F32: 885 | G32: 745.8 | H32: 276
A33: C5 | B33: 253 | C33: Over_Ref_Cabinet | D33: Bottom_Clad | E33: 5 | F33: 5 | G33: 942 | H33: 760
A34: C5 | B34: 260 | C34: Over_Ref_Cabinet | D34: Top_Clad | E34: 951 | F34: 5 | G34: 942 | H34: 760
A35: C5 | B35: 252 | C35: Over_Ref_Cabinet | D35: Back_Clad | E35: 1897 | F35: 5 | G35: 457 | H35: 942 | I35: yes
A36: C5 | B36: 235 | C36: Island_2_Induction_773 | D36: DrawerFront_Insert | E36: 2358 | F36: 5 | G36: 68 | H36: 745.8 | I36: yes
A37: C5 | B37: 268 | C37: Upper_400 | D37: Back_Clad | E37: 5 | F37: 769 | G37: 914 | H37: 392
A38: C5 | B38: 272 | C38: Upper_400 | D38: Side_Clad | E38: 951 | F38: 769 | G38: 914 | H38: 310
A39: C5 | B39: 231 | C39: Island_1_Racks_473 | D39: Plinth_Side_Clad | E39: 1897 | F39: 951 | G39: 474 | H39: 100
A40: C5 | B40: 240 | C40: Island_2_Induction_773 | D40: Plinth_Side_Clad | E40: 1897 | F40: 1055 | G40: 474 | H40: 100
A41: C5 | B41: 284 | C41: Upper_Over_Washer | D41: Pipe_Chase_Side_Clad | E41: 951 | F41: 1083 | G41: 914 | H41: 124
...
